
------Start------

  时间：2017-02-04 09:17:08,592   线程ID:[8]   日志级别：INFO   
  [2017-02-04 09:17:08]DoubleX.Infrastructure.Core.Exceptions.MessageException: 引发类型为“DoubleX.Infrastructure.Core.Exceptions.MessageException”的异常。
   在 DoubleX.Module.Organize.EmployeeService.Login(String account, String password) 位置 e:\Project\API站点\source\DoubleX\Module\DoubleX.Module.Organize\Service\EmployeeService.cs:行号 34
   在 System.Dynamic.UpdateDelegates.UpdateAndExecute3[T0,T1,T2,TRet](CallSite site, T0 arg0, T1 arg1, T2 arg2)
   在 DoubleX.Applaction.Web.Areas.Api.Controllers.OrganizeController.EmployeeLogin(RequestModel request) 位置 e:\Project\API站点\source\DoubleX\Applaction\DoubleX.Applaction.Apisite\Areas\Api\Controllers\OrganizeController.cs:行号 39
   在 lambda_method(Closure , Object , Object[] )
   在 System.Web.Http.Controllers.ReflectedHttpActionDescriptor.ActionExecutor.<>c__DisplayClass10.<GetExecutor>b__9(Object instance, Object[] methodParameters)
   在 System.Web.Http.Controllers.ReflectedHttpActionDescriptor.ActionExecutor.Execute(Object instance, Object[] arguments)
   在 System.Web.Http.Controllers.ReflectedHttpActionDescriptor.ExecuteAsync(HttpControllerContext controllerContext, IDictionary`2 arguments, CancellationToken cancellationToken)
--- 引发异常的上一位置中堆栈跟踪的末尾 ---
   在 System.Runtime.CompilerServices.TaskAwaiter.ThrowForNonSuccess(Task task)
   在 System.Runtime.CompilerServices.TaskAwaiter.HandleNonSuccessAndDebuggerNotification(Task task)
   在 System.Runtime.CompilerServices.TaskAwaiter`1.GetResult()
   在 System.Web.Http.Controllers.ApiControllerActionInvoker.<InvokeActionAsyncCore>d__0.MoveNext()
--- 引发异常的上一位置中堆栈跟踪的末尾 ---
   在 System.Runtime.CompilerServices.TaskAwaiter.ThrowForNonSuccess(Task task)
   在 System.Runtime.CompilerServices.TaskAwaiter.HandleNonSuccessAndDebuggerNotification(Task task)
   在 System.Runtime.CompilerServices.TaskAwaiter`1.GetResult()
   在 System.Web.Http.Filters.ActionFilterAttribute.<CallOnActionExecutedAsync>d__5.MoveNext()
--- 引发异常的上一位置中堆栈跟踪的末尾 ---
   在 System.Runtime.ExceptionServices.ExceptionDispatchInfo.Throw()
   在 System.Web.Http.Filters.ActionFilterAttribute.<CallOnActionExecutedAsync>d__5.MoveNext()
--- 引发异常的上一位置中堆栈跟踪的末尾 ---
   在 System.Runtime.CompilerServices.TaskAwaiter.ThrowForNonSuccess(Task task)
   在 System.Runtime.CompilerServices.TaskAwaiter.HandleNonSuccessAndDebuggerNotification(Task task)
   在 System.Runtime.CompilerServices.TaskAwaiter`1.GetResult()
   在 System.Web.Http.Filters.ActionFilterAttribute.<ExecuteActionFilterAsyncCore>d__0.MoveNext()
--- 引发异常的上一位置中堆栈跟踪的末尾 ---
   在 System.Runtime.CompilerServices.TaskAwaiter.ThrowForNonSuccess(Task task)
   在 System.Runtime.CompilerServices.TaskAwaiter.HandleNonSuccessAndDebuggerNotification(Task task)
   在 System.Runtime.CompilerServices.TaskAwaiter`1.GetResult()
   在 System.Web.Http.Controllers.ActionFilterResult.<ExecuteAsync>d__2.MoveNext()
--- 引发异常的上一位置中堆栈跟踪的末尾 ---
   在 System.Runtime.CompilerServices.TaskAwaiter.ThrowForNonSuccess(Task task)
   在 System.Runtime.CompilerServices.TaskAwaiter.HandleNonSuccessAndDebuggerNotification(Task task)
   在 System.Runtime.CompilerServices.TaskAwaiter`1.GetResult()
   在 System.Web.Http.Controllers.ExceptionFilterResult.<ExecuteAsync>d__0.MoveNext()  
 
-------End-------

------Start------

  时间：2017-02-04 09:18:01,372   线程ID:[7]   日志级别：INFO   
  [2017-02-04 09:18:01]DoubleX.Infrastructure.Core.Exceptions.MessageException: 引发类型为“DoubleX.Infrastructure.Core.Exceptions.MessageException”的异常。
   在 DoubleX.Module.Organize.EmployeeService.Login(String account, String password) 位置 e:\Project\API站点\source\DoubleX\Module\DoubleX.Module.Organize\Service\EmployeeService.cs:行号 34
   在 System.Dynamic.UpdateDelegates.UpdateAndExecute3[T0,T1,T2,TRet](CallSite site, T0 arg0, T1 arg1, T2 arg2)
   在 DoubleX.Applaction.Web.Areas.Api.Controllers.OrganizeController.EmployeeLogin(RequestModel request) 位置 e:\Project\API站点\source\DoubleX\Applaction\DoubleX.Applaction.Apisite\Areas\Api\Controllers\OrganizeController.cs:行号 39
   在 lambda_method(Closure , Object , Object[] )
   在 System.Web.Http.Controllers.ReflectedHttpActionDescriptor.ActionExecutor.<>c__DisplayClass10.<GetExecutor>b__9(Object instance, Object[] methodParameters)
   在 System.Web.Http.Controllers.ReflectedHttpActionDescriptor.ActionExecutor.Execute(Object instance, Object[] arguments)
   在 System.Web.Http.Controllers.ReflectedHttpActionDescriptor.ExecuteAsync(HttpControllerContext controllerContext, IDictionary`2 arguments, CancellationToken cancellationToken)
--- 引发异常的上一位置中堆栈跟踪的末尾 ---
   在 System.Runtime.CompilerServices.TaskAwaiter.ThrowForNonSuccess(Task task)
   在 System.Runtime.CompilerServices.TaskAwaiter.HandleNonSuccessAndDebuggerNotification(Task task)
   在 System.Runtime.CompilerServices.TaskAwaiter`1.GetResult()
   在 System.Web.Http.Controllers.ApiControllerActionInvoker.<InvokeActionAsyncCore>d__0.MoveNext()
--- 引发异常的上一位置中堆栈跟踪的末尾 ---
   在 System.Runtime.CompilerServices.TaskAwaiter.ThrowForNonSuccess(Task task)
   在 System.Runtime.CompilerServices.TaskAwaiter.HandleNonSuccessAndDebuggerNotification(Task task)
   在 System.Runtime.CompilerServices.TaskAwaiter`1.GetResult()
   在 System.Web.Http.Filters.ActionFilterAttribute.<CallOnActionExecutedAsync>d__5.MoveNext()
--- 引发异常的上一位置中堆栈跟踪的末尾 ---
   在 System.Runtime.ExceptionServices.ExceptionDispatchInfo.Throw()
   在 System.Web.Http.Filters.ActionFilterAttribute.<CallOnActionExecutedAsync>d__5.MoveNext()
--- 引发异常的上一位置中堆栈跟踪的末尾 ---
   在 System.Runtime.CompilerServices.TaskAwaiter.ThrowForNonSuccess(Task task)
   在 System.Runtime.CompilerServices.TaskAwaiter.HandleNonSuccessAndDebuggerNotification(Task task)
   在 System.Runtime.CompilerServices.TaskAwaiter`1.GetResult()
   在 System.Web.Http.Filters.ActionFilterAttribute.<ExecuteActionFilterAsyncCore>d__0.MoveNext()
--- 引发异常的上一位置中堆栈跟踪的末尾 ---
   在 System.Runtime.CompilerServices.TaskAwaiter.ThrowForNonSuccess(Task task)
   在 System.Runtime.CompilerServices.TaskAwaiter.HandleNonSuccessAndDebuggerNotification(Task task)
   在 System.Runtime.CompilerServices.TaskAwaiter`1.GetResult()
   在 System.Web.Http.Controllers.ActionFilterResult.<ExecuteAsync>d__2.MoveNext()
--- 引发异常的上一位置中堆栈跟踪的末尾 ---
   在 System.Runtime.CompilerServices.TaskAwaiter.ThrowForNonSuccess(Task task)
   在 System.Runtime.CompilerServices.TaskAwaiter.HandleNonSuccessAndDebuggerNotification(Task task)
   在 System.Runtime.CompilerServices.TaskAwaiter`1.GetResult()
   在 System.Web.Http.Controllers.ExceptionFilterResult.<ExecuteAsync>d__0.MoveNext()  
 
-------End-------

------Start------

  时间：2017-02-04 09:18:12,498   线程ID:[6]   日志级别：INFO   
  [2017-02-04 09:18:12]DoubleX.Infrastructure.Core.Exceptions.MessageException: 引发类型为“DoubleX.Infrastructure.Core.Exceptions.MessageException”的异常。
   在 DoubleX.Module.Organize.EmployeeService.Login(String account, String password) 位置 e:\Project\API站点\source\DoubleX\Module\DoubleX.Module.Organize\Service\EmployeeService.cs:行号 52
   在 DoubleX.Applaction.Web.Areas.Api.Controllers.OrganizeController.EmployeeLogin(RequestModel request) 位置 e:\Project\API站点\source\DoubleX\Applaction\DoubleX.Applaction.Apisite\Areas\Api\Controllers\OrganizeController.cs:行号 39
   在 lambda_method(Closure , Object , Object[] )
   在 System.Web.Http.Controllers.ReflectedHttpActionDescriptor.ActionExecutor.<>c__DisplayClass10.<GetExecutor>b__9(Object instance, Object[] methodParameters)
   在 System.Web.Http.Controllers.ReflectedHttpActionDescriptor.ActionExecutor.Execute(Object instance, Object[] arguments)
   在 System.Web.Http.Controllers.ReflectedHttpActionDescriptor.ExecuteAsync(HttpControllerContext controllerContext, IDictionary`2 arguments, CancellationToken cancellationToken)
--- 引发异常的上一位置中堆栈跟踪的末尾 ---
   在 System.Runtime.CompilerServices.TaskAwaiter.ThrowForNonSuccess(Task task)
   在 System.Runtime.CompilerServices.TaskAwaiter.HandleNonSuccessAndDebuggerNotification(Task task)
   在 System.Runtime.CompilerServices.TaskAwaiter`1.GetResult()
   在 System.Web.Http.Controllers.ApiControllerActionInvoker.<InvokeActionAsyncCore>d__0.MoveNext()
--- 引发异常的上一位置中堆栈跟踪的末尾 ---
   在 System.Runtime.CompilerServices.TaskAwaiter.ThrowForNonSuccess(Task task)
   在 System.Runtime.CompilerServices.TaskAwaiter.HandleNonSuccessAndDebuggerNotification(Task task)
   在 System.Runtime.CompilerServices.TaskAwaiter`1.GetResult()
   在 System.Web.Http.Filters.ActionFilterAttribute.<CallOnActionExecutedAsync>d__5.MoveNext()
--- 引发异常的上一位置中堆栈跟踪的末尾 ---
   在 System.Runtime.ExceptionServices.ExceptionDispatchInfo.Throw()
   在 System.Web.Http.Filters.ActionFilterAttribute.<CallOnActionExecutedAsync>d__5.MoveNext()
--- 引发异常的上一位置中堆栈跟踪的末尾 ---
   在 System.Runtime.CompilerServices.TaskAwaiter.ThrowForNonSuccess(Task task)
   在 System.Runtime.CompilerServices.TaskAwaiter.HandleNonSuccessAndDebuggerNotification(Task task)
   在 System.Runtime.CompilerServices.TaskAwaiter`1.GetResult()
   在 System.Web.Http.Filters.ActionFilterAttribute.<ExecuteActionFilterAsyncCore>d__0.MoveNext()
--- 引发异常的上一位置中堆栈跟踪的末尾 ---
   在 System.Runtime.CompilerServices.TaskAwaiter.ThrowForNonSuccess(Task task)
   在 System.Runtime.CompilerServices.TaskAwaiter.HandleNonSuccessAndDebuggerNotification(Task task)
   在 System.Runtime.CompilerServices.TaskAwaiter`1.GetResult()
   在 System.Web.Http.Controllers.ActionFilterResult.<ExecuteAsync>d__2.MoveNext()
--- 引发异常的上一位置中堆栈跟踪的末尾 ---
   在 System.Runtime.CompilerServices.TaskAwaiter.ThrowForNonSuccess(Task task)
   在 System.Runtime.CompilerServices.TaskAwaiter.HandleNonSuccessAndDebuggerNotification(Task task)
   在 System.Runtime.CompilerServices.TaskAwaiter`1.GetResult()
   在 System.Web.Http.Controllers.ExceptionFilterResult.<ExecuteAsync>d__0.MoveNext()  
 
-------End-------

------Start------

  时间：2017-02-04 09:18:25,645   线程ID:[6]   日志级别：INFO   
  [2017-02-04 09:18:25]DoubleX.Infrastructure.Core.Exceptions.MessageException: 引发类型为“DoubleX.Infrastructure.Core.Exceptions.MessageException”的异常。
   在 DoubleX.Module.Organize.EmployeeService.Login(String account, String password) 位置 e:\Project\API站点\source\DoubleX\Module\DoubleX.Module.Organize\Service\EmployeeService.cs:行号 58
   在 DoubleX.Applaction.Web.Areas.Api.Controllers.OrganizeController.EmployeeLogin(RequestModel request) 位置 e:\Project\API站点\source\DoubleX\Applaction\DoubleX.Applaction.Apisite\Areas\Api\Controllers\OrganizeController.cs:行号 39
   在 lambda_method(Closure , Object , Object[] )
   在 System.Web.Http.Controllers.ReflectedHttpActionDescriptor.ActionExecutor.<>c__DisplayClass10.<GetExecutor>b__9(Object instance, Object[] methodParameters)
   在 System.Web.Http.Controllers.ReflectedHttpActionDescriptor.ActionExecutor.Execute(Object instance, Object[] arguments)
   在 System.Web.Http.Controllers.ReflectedHttpActionDescriptor.ExecuteAsync(HttpControllerContext controllerContext, IDictionary`2 arguments, CancellationToken cancellationToken)
--- 引发异常的上一位置中堆栈跟踪的末尾 ---
   在 System.Runtime.CompilerServices.TaskAwaiter.ThrowForNonSuccess(Task task)
   在 System.Runtime.CompilerServices.TaskAwaiter.HandleNonSuccessAndDebuggerNotification(Task task)
   在 System.Runtime.CompilerServices.TaskAwaiter`1.GetResult()
   在 System.Web.Http.Controllers.ApiControllerActionInvoker.<InvokeActionAsyncCore>d__0.MoveNext()
--- 引发异常的上一位置中堆栈跟踪的末尾 ---
   在 System.Runtime.CompilerServices.TaskAwaiter.ThrowForNonSuccess(Task task)
   在 System.Runtime.CompilerServices.TaskAwaiter.HandleNonSuccessAndDebuggerNotification(Task task)
   在 System.Runtime.CompilerServices.TaskAwaiter`1.GetResult()
   在 System.Web.Http.Filters.ActionFilterAttribute.<CallOnActionExecutedAsync>d__5.MoveNext()
--- 引发异常的上一位置中堆栈跟踪的末尾 ---
   在 System.Runtime.ExceptionServices.ExceptionDispatchInfo.Throw()
   在 System.Web.Http.Filters.ActionFilterAttribute.<CallOnActionExecutedAsync>d__5.MoveNext()
--- 引发异常的上一位置中堆栈跟踪的末尾 ---
   在 System.Runtime.CompilerServices.TaskAwaiter.ThrowForNonSuccess(Task task)
   在 System.Runtime.CompilerServices.TaskAwaiter.HandleNonSuccessAndDebuggerNotification(Task task)
   在 System.Runtime.CompilerServices.TaskAwaiter`1.GetResult()
   在 System.Web.Http.Filters.ActionFilterAttribute.<ExecuteActionFilterAsyncCore>d__0.MoveNext()
--- 引发异常的上一位置中堆栈跟踪的末尾 ---
   在 System.Runtime.CompilerServices.TaskAwaiter.ThrowForNonSuccess(Task task)
   在 System.Runtime.CompilerServices.TaskAwaiter.HandleNonSuccessAndDebuggerNotification(Task task)
   在 System.Runtime.CompilerServices.TaskAwaiter`1.GetResult()
   在 System.Web.Http.Controllers.ActionFilterResult.<ExecuteAsync>d__2.MoveNext()
--- 引发异常的上一位置中堆栈跟踪的末尾 ---
   在 System.Runtime.CompilerServices.TaskAwaiter.ThrowForNonSuccess(Task task)
   在 System.Runtime.CompilerServices.TaskAwaiter.HandleNonSuccessAndDebuggerNotification(Task task)
   在 System.Runtime.CompilerServices.TaskAwaiter`1.GetResult()
   在 System.Web.Http.Controllers.ExceptionFilterResult.<ExecuteAsync>d__0.MoveNext()  
 
-------End-------

------Start------

  时间：2017-02-04 09:18:28,856   线程ID:[7]   日志级别：INFO   
  [2017-02-04 09:18:28]DoubleX.Infrastructure.Core.Exceptions.MessageException: 引发类型为“DoubleX.Infrastructure.Core.Exceptions.MessageException”的异常。
   在 DoubleX.Module.Organize.EmployeeService.Login(String account, String password) 位置 e:\Project\API站点\source\DoubleX\Module\DoubleX.Module.Organize\Service\EmployeeService.cs:行号 58
   在 DoubleX.Applaction.Web.Areas.Api.Controllers.OrganizeController.EmployeeLogin(RequestModel request) 位置 e:\Project\API站点\source\DoubleX\Applaction\DoubleX.Applaction.Apisite\Areas\Api\Controllers\OrganizeController.cs:行号 39
   在 lambda_method(Closure , Object , Object[] )
   在 System.Web.Http.Controllers.ReflectedHttpActionDescriptor.ActionExecutor.<>c__DisplayClass10.<GetExecutor>b__9(Object instance, Object[] methodParameters)
   在 System.Web.Http.Controllers.ReflectedHttpActionDescriptor.ActionExecutor.Execute(Object instance, Object[] arguments)
   在 System.Web.Http.Controllers.ReflectedHttpActionDescriptor.ExecuteAsync(HttpControllerContext controllerContext, IDictionary`2 arguments, CancellationToken cancellationToken)
--- 引发异常的上一位置中堆栈跟踪的末尾 ---
   在 System.Runtime.CompilerServices.TaskAwaiter.ThrowForNonSuccess(Task task)
   在 System.Runtime.CompilerServices.TaskAwaiter.HandleNonSuccessAndDebuggerNotification(Task task)
   在 System.Runtime.CompilerServices.TaskAwaiter`1.GetResult()
   在 System.Web.Http.Controllers.ApiControllerActionInvoker.<InvokeActionAsyncCore>d__0.MoveNext()
--- 引发异常的上一位置中堆栈跟踪的末尾 ---
   在 System.Runtime.CompilerServices.TaskAwaiter.ThrowForNonSuccess(Task task)
   在 System.Runtime.CompilerServices.TaskAwaiter.HandleNonSuccessAndDebuggerNotification(Task task)
   在 System.Runtime.CompilerServices.TaskAwaiter`1.GetResult()
   在 System.Web.Http.Filters.ActionFilterAttribute.<CallOnActionExecutedAsync>d__5.MoveNext()
--- 引发异常的上一位置中堆栈跟踪的末尾 ---
   在 System.Runtime.ExceptionServices.ExceptionDispatchInfo.Throw()
   在 System.Web.Http.Filters.ActionFilterAttribute.<CallOnActionExecutedAsync>d__5.MoveNext()
--- 引发异常的上一位置中堆栈跟踪的末尾 ---
   在 System.Runtime.CompilerServices.TaskAwaiter.ThrowForNonSuccess(Task task)
   在 System.Runtime.CompilerServices.TaskAwaiter.HandleNonSuccessAndDebuggerNotification(Task task)
   在 System.Runtime.CompilerServices.TaskAwaiter`1.GetResult()
   在 System.Web.Http.Filters.ActionFilterAttribute.<ExecuteActionFilterAsyncCore>d__0.MoveNext()
--- 引发异常的上一位置中堆栈跟踪的末尾 ---
   在 System.Runtime.CompilerServices.TaskAwaiter.ThrowForNonSuccess(Task task)
   在 System.Runtime.CompilerServices.TaskAwaiter.HandleNonSuccessAndDebuggerNotification(Task task)
   在 System.Runtime.CompilerServices.TaskAwaiter`1.GetResult()
   在 System.Web.Http.Controllers.ActionFilterResult.<ExecuteAsync>d__2.MoveNext()
--- 引发异常的上一位置中堆栈跟踪的末尾 ---
   在 System.Runtime.CompilerServices.TaskAwaiter.ThrowForNonSuccess(Task task)
   在 System.Runtime.CompilerServices.TaskAwaiter.HandleNonSuccessAndDebuggerNotification(Task task)
   在 System.Runtime.CompilerServices.TaskAwaiter`1.GetResult()
   在 System.Web.Http.Controllers.ExceptionFilterResult.<ExecuteAsync>d__0.MoveNext()  
 
-------End-------
