
------Start------

  时间：2017-03-13 14:02:23,250   线程ID:[10]   日志级别：INFO   
  [2017-03-13 14:02:23]DoubleX.Infrastructure.Core.Exceptions.MessageException: 引发类型为“DoubleX.Infrastructure.Core.Exceptions.MessageException”的异常。
   在 DoubleX.Framework.Interceptor.ServiceLogInterceptor.Intercept(IInvocation invocation) 位置 F:\work\OpenAPI_v20170117\UTH.OpenAPI.Web\Framework\DoubleX.Framework.Interceptor\Log\ServiceLogInterceptor.cs:行号 32
   在 Castle.DynamicProxy.AbstractInvocation.Proceed()
   在 Castle.Proxies.IService`2Proxy.Login(String account, String password, String clientIp)
   在 DoubleX.Applaction.Apisite.Areas.Api.Controllers.MemberController.MemberLogin(RequestModel request) 位置 F:\work\OpenAPI_v20170117\UTH.OpenAPI.Web\Applaction\DoubleX.Applaction.Apisite\Areas\Api\Controllers\MemberController.cs:行号 156
   在 lambda_method(Closure , Object , Object[] )
   在 System.Web.Http.Controllers.ReflectedHttpActionDescriptor.ActionExecutor.<>c__DisplayClass10.<GetExecutor>b__9(Object instance, Object[] methodParameters)
   在 System.Web.Http.Controllers.ReflectedHttpActionDescriptor.ActionExecutor.Execute(Object instance, Object[] arguments)
   在 System.Web.Http.Controllers.ReflectedHttpActionDescriptor.ExecuteAsync(HttpControllerContext controllerContext, IDictionary`2 arguments, CancellationToken cancellationToken)
--- 引发异常的上一位置中堆栈跟踪的末尾 ---
   在 System.Runtime.CompilerServices.TaskAwaiter.ThrowForNonSuccess(Task task)
   在 System.Runtime.CompilerServices.TaskAwaiter.HandleNonSuccessAndDebuggerNotification(Task task)
   在 System.Web.Http.Controllers.ApiControllerActionInvoker.<InvokeActionAsyncCore>d__0.MoveNext()
--- 引发异常的上一位置中堆栈跟踪的末尾 ---
   在 System.Runtime.CompilerServices.TaskAwaiter.ThrowForNonSuccess(Task task)
   在 System.Runtime.CompilerServices.TaskAwaiter.HandleNonSuccessAndDebuggerNotification(Task task)
   在 System.Web.Http.Filters.ActionFilterAttribute.<CallOnActionExecutedAsync>d__5.MoveNext()
--- 引发异常的上一位置中堆栈跟踪的末尾 ---
   在 System.Web.Http.Filters.ActionFilterAttribute.<CallOnActionExecutedAsync>d__5.MoveNext()
--- 引发异常的上一位置中堆栈跟踪的末尾 ---
   在 System.Runtime.CompilerServices.TaskAwaiter.ThrowForNonSuccess(Task task)
   在 System.Runtime.CompilerServices.TaskAwaiter.HandleNonSuccessAndDebuggerNotification(Task task)
   在 System.Web.Http.Filters.ActionFilterAttribute.<ExecuteActionFilterAsyncCore>d__0.MoveNext()
--- 引发异常的上一位置中堆栈跟踪的末尾 ---
   在 System.Runtime.CompilerServices.TaskAwaiter.ThrowForNonSuccess(Task task)
   在 System.Runtime.CompilerServices.TaskAwaiter.HandleNonSuccessAndDebuggerNotification(Task task)
   在 System.Web.Http.Controllers.ActionFilterResult.<ExecuteAsync>d__2.MoveNext()
--- 引发异常的上一位置中堆栈跟踪的末尾 ---
   在 System.Runtime.CompilerServices.TaskAwaiter.ThrowForNonSuccess(Task task)
   在 System.Runtime.CompilerServices.TaskAwaiter.HandleNonSuccessAndDebuggerNotification(Task task)
   在 System.Web.Http.Controllers.ExceptionFilterResult.<ExecuteAsync>d__0.MoveNext()  
 
-------End-------

------Start------

  时间：2017-03-13 14:02:37,719   线程ID:[12]   日志级别：INFO   
  [2017-03-13 14:02:37]DoubleX.Infrastructure.Core.Exceptions.MessageException: 引发类型为“DoubleX.Infrastructure.Core.Exceptions.MessageException”的异常。
   在 DoubleX.Framework.Interceptor.ServiceLogInterceptor.Intercept(IInvocation invocation) 位置 F:\work\OpenAPI_v20170117\UTH.OpenAPI.Web\Framework\DoubleX.Framework.Interceptor\Log\ServiceLogInterceptor.cs:行号 32
   在 Castle.DynamicProxy.AbstractInvocation.Proceed()
   在 Castle.Proxies.IService`2Proxy.Login(String account, String password, String clientIp)
   在 DoubleX.Applaction.Apisite.Areas.Api.Controllers.MemberController.MemberLogin(RequestModel request) 位置 F:\work\OpenAPI_v20170117\UTH.OpenAPI.Web\Applaction\DoubleX.Applaction.Apisite\Areas\Api\Controllers\MemberController.cs:行号 156
   在 lambda_method(Closure , Object , Object[] )
   在 System.Web.Http.Controllers.ReflectedHttpActionDescriptor.ActionExecutor.<>c__DisplayClass10.<GetExecutor>b__9(Object instance, Object[] methodParameters)
   在 System.Web.Http.Controllers.ReflectedHttpActionDescriptor.ActionExecutor.Execute(Object instance, Object[] arguments)
   在 System.Web.Http.Controllers.ReflectedHttpActionDescriptor.ExecuteAsync(HttpControllerContext controllerContext, IDictionary`2 arguments, CancellationToken cancellationToken)
--- 引发异常的上一位置中堆栈跟踪的末尾 ---
   在 System.Runtime.CompilerServices.TaskAwaiter.ThrowForNonSuccess(Task task)
   在 System.Runtime.CompilerServices.TaskAwaiter.HandleNonSuccessAndDebuggerNotification(Task task)
   在 System.Web.Http.Controllers.ApiControllerActionInvoker.<InvokeActionAsyncCore>d__0.MoveNext()
--- 引发异常的上一位置中堆栈跟踪的末尾 ---
   在 System.Runtime.CompilerServices.TaskAwaiter.ThrowForNonSuccess(Task task)
   在 System.Runtime.CompilerServices.TaskAwaiter.HandleNonSuccessAndDebuggerNotification(Task task)
   在 System.Web.Http.Filters.ActionFilterAttribute.<CallOnActionExecutedAsync>d__5.MoveNext()
--- 引发异常的上一位置中堆栈跟踪的末尾 ---
   在 System.Web.Http.Filters.ActionFilterAttribute.<CallOnActionExecutedAsync>d__5.MoveNext()
--- 引发异常的上一位置中堆栈跟踪的末尾 ---
   在 System.Runtime.CompilerServices.TaskAwaiter.ThrowForNonSuccess(Task task)
   在 System.Runtime.CompilerServices.TaskAwaiter.HandleNonSuccessAndDebuggerNotification(Task task)
   在 System.Web.Http.Filters.ActionFilterAttribute.<ExecuteActionFilterAsyncCore>d__0.MoveNext()
--- 引发异常的上一位置中堆栈跟踪的末尾 ---
   在 System.Runtime.CompilerServices.TaskAwaiter.ThrowForNonSuccess(Task task)
   在 System.Runtime.CompilerServices.TaskAwaiter.HandleNonSuccessAndDebuggerNotification(Task task)
   在 System.Web.Http.Controllers.ActionFilterResult.<ExecuteAsync>d__2.MoveNext()
--- 引发异常的上一位置中堆栈跟踪的末尾 ---
   在 System.Runtime.CompilerServices.TaskAwaiter.ThrowForNonSuccess(Task task)
   在 System.Runtime.CompilerServices.TaskAwaiter.HandleNonSuccessAndDebuggerNotification(Task task)
   在 System.Web.Http.Controllers.ExceptionFilterResult.<ExecuteAsync>d__0.MoveNext()  
 
-------End-------

------Start------

  时间：2017-03-13 14:04:46,693   线程ID:[8]   日志级别：INFO   
  [2017-03-13 14:04:46]DoubleX.Infrastructure.Core.Exceptions.MessageException: 引发类型为“DoubleX.Infrastructure.Core.Exceptions.MessageException”的异常。
   在 DoubleX.Framework.Interceptor.ServiceLogInterceptor.Intercept(IInvocation invocation) 位置 F:\work\OpenAPI_v20170117\UTH.OpenAPI.Web\Framework\DoubleX.Framework.Interceptor\Log\ServiceLogInterceptor.cs:行号 32
   在 Castle.DynamicProxy.AbstractInvocation.Proceed()
   在 Castle.Proxies.IService`2Proxy.Login(String account, String password, String clientIp)
   在 DoubleX.Applaction.Apisite.Areas.Api.Controllers.MemberController.MemberLogin(RequestModel request) 位置 F:\work\OpenAPI_v20170117\UTH.OpenAPI.Web\Applaction\DoubleX.Applaction.Apisite\Areas\Api\Controllers\MemberController.cs:行号 156
   在 lambda_method(Closure , Object , Object[] )
   在 System.Web.Http.Controllers.ReflectedHttpActionDescriptor.ActionExecutor.<>c__DisplayClass10.<GetExecutor>b__9(Object instance, Object[] methodParameters)
   在 System.Web.Http.Controllers.ReflectedHttpActionDescriptor.ActionExecutor.Execute(Object instance, Object[] arguments)
   在 System.Web.Http.Controllers.ReflectedHttpActionDescriptor.ExecuteAsync(HttpControllerContext controllerContext, IDictionary`2 arguments, CancellationToken cancellationToken)
--- 引发异常的上一位置中堆栈跟踪的末尾 ---
   在 System.Runtime.CompilerServices.TaskAwaiter.ThrowForNonSuccess(Task task)
   在 System.Runtime.CompilerServices.TaskAwaiter.HandleNonSuccessAndDebuggerNotification(Task task)
   在 System.Web.Http.Controllers.ApiControllerActionInvoker.<InvokeActionAsyncCore>d__0.MoveNext()
--- 引发异常的上一位置中堆栈跟踪的末尾 ---
   在 System.Runtime.CompilerServices.TaskAwaiter.ThrowForNonSuccess(Task task)
   在 System.Runtime.CompilerServices.TaskAwaiter.HandleNonSuccessAndDebuggerNotification(Task task)
   在 System.Web.Http.Filters.ActionFilterAttribute.<CallOnActionExecutedAsync>d__5.MoveNext()
--- 引发异常的上一位置中堆栈跟踪的末尾 ---
   在 System.Web.Http.Filters.ActionFilterAttribute.<CallOnActionExecutedAsync>d__5.MoveNext()
--- 引发异常的上一位置中堆栈跟踪的末尾 ---
   在 System.Runtime.CompilerServices.TaskAwaiter.ThrowForNonSuccess(Task task)
   在 System.Runtime.CompilerServices.TaskAwaiter.HandleNonSuccessAndDebuggerNotification(Task task)
   在 System.Web.Http.Filters.ActionFilterAttribute.<ExecuteActionFilterAsyncCore>d__0.MoveNext()
--- 引发异常的上一位置中堆栈跟踪的末尾 ---
   在 System.Runtime.CompilerServices.TaskAwaiter.ThrowForNonSuccess(Task task)
   在 System.Runtime.CompilerServices.TaskAwaiter.HandleNonSuccessAndDebuggerNotification(Task task)
   在 System.Web.Http.Controllers.ActionFilterResult.<ExecuteAsync>d__2.MoveNext()
--- 引发异常的上一位置中堆栈跟踪的末尾 ---
   在 System.Runtime.CompilerServices.TaskAwaiter.ThrowForNonSuccess(Task task)
   在 System.Runtime.CompilerServices.TaskAwaiter.HandleNonSuccessAndDebuggerNotification(Task task)
   在 System.Web.Http.Controllers.ExceptionFilterResult.<ExecuteAsync>d__0.MoveNext()  
 
-------End-------

------Start------

  时间：2017-03-13 14:06:41,056   线程ID:[12]   日志级别：INFO   
  [2017-03-13 14:06:41]DoubleX.Infrastructure.Core.Exceptions.MessageException: 引发类型为“DoubleX.Infrastructure.Core.Exceptions.MessageException”的异常。
   在 DoubleX.Framework.Interceptor.ServiceLogInterceptor.Intercept(IInvocation invocation) 位置 F:\work\OpenAPI_v20170117\UTH.OpenAPI.Web\Framework\DoubleX.Framework.Interceptor\Log\ServiceLogInterceptor.cs:行号 32
   在 Castle.DynamicProxy.AbstractInvocation.Proceed()
   在 Castle.Proxies.IService`2Proxy.Login(String account, String password, String clientIp)
   在 DoubleX.Applaction.Apisite.Areas.Api.Controllers.MemberController.MemberLogin(RequestModel request) 位置 F:\work\OpenAPI_v20170117\UTH.OpenAPI.Web\Applaction\DoubleX.Applaction.Apisite\Areas\Api\Controllers\MemberController.cs:行号 156
   在 lambda_method(Closure , Object , Object[] )
   在 System.Web.Http.Controllers.ReflectedHttpActionDescriptor.ActionExecutor.<>c__DisplayClass10.<GetExecutor>b__9(Object instance, Object[] methodParameters)
   在 System.Web.Http.Controllers.ReflectedHttpActionDescriptor.ActionExecutor.Execute(Object instance, Object[] arguments)
   在 System.Web.Http.Controllers.ReflectedHttpActionDescriptor.ExecuteAsync(HttpControllerContext controllerContext, IDictionary`2 arguments, CancellationToken cancellationToken)
--- 引发异常的上一位置中堆栈跟踪的末尾 ---
   在 System.Runtime.CompilerServices.TaskAwaiter.ThrowForNonSuccess(Task task)
   在 System.Runtime.CompilerServices.TaskAwaiter.HandleNonSuccessAndDebuggerNotification(Task task)
   在 System.Web.Http.Controllers.ApiControllerActionInvoker.<InvokeActionAsyncCore>d__0.MoveNext()
--- 引发异常的上一位置中堆栈跟踪的末尾 ---
   在 System.Runtime.CompilerServices.TaskAwaiter.ThrowForNonSuccess(Task task)
   在 System.Runtime.CompilerServices.TaskAwaiter.HandleNonSuccessAndDebuggerNotification(Task task)
   在 System.Web.Http.Filters.ActionFilterAttribute.<CallOnActionExecutedAsync>d__5.MoveNext()
--- 引发异常的上一位置中堆栈跟踪的末尾 ---
   在 System.Web.Http.Filters.ActionFilterAttribute.<CallOnActionExecutedAsync>d__5.MoveNext()
--- 引发异常的上一位置中堆栈跟踪的末尾 ---
   在 System.Runtime.CompilerServices.TaskAwaiter.ThrowForNonSuccess(Task task)
   在 System.Runtime.CompilerServices.TaskAwaiter.HandleNonSuccessAndDebuggerNotification(Task task)
   在 System.Web.Http.Filters.ActionFilterAttribute.<ExecuteActionFilterAsyncCore>d__0.MoveNext()
--- 引发异常的上一位置中堆栈跟踪的末尾 ---
   在 System.Runtime.CompilerServices.TaskAwaiter.ThrowForNonSuccess(Task task)
   在 System.Runtime.CompilerServices.TaskAwaiter.HandleNonSuccessAndDebuggerNotification(Task task)
   在 System.Web.Http.Controllers.ActionFilterResult.<ExecuteAsync>d__2.MoveNext()
--- 引发异常的上一位置中堆栈跟踪的末尾 ---
   在 System.Runtime.CompilerServices.TaskAwaiter.ThrowForNonSuccess(Task task)
   在 System.Runtime.CompilerServices.TaskAwaiter.HandleNonSuccessAndDebuggerNotification(Task task)
   在 System.Web.Http.Controllers.ExceptionFilterResult.<ExecuteAsync>d__0.MoveNext()  
 
-------End-------
